Workbook
Name Career_Stage: Data!$B$3:$B$7
Name Core_Exercise: 'Core Exercise'!$A$2:$A$8
Name Core_XT_Training_Sections: Data!$H$3:$H$5
Name Interview_Outcome: Data!$C$3:$C$5
Name React_Exercise: 'React Exercise'!$A$2:$A$8
Name React_Training_Sections: Data!$J$3
Name Rejection_Reason: Data!$E$3:$E$5
Name Scoring_Architecture: Data!$D$3:$D$7
Name Scoring_Development: Data!$F$3:$F$7
Name Will_You_Take_Person: Data!$I$3:$I$4

Sheet 1 - HTML, CSS & NFRs
B2: Experience Engineering Hiring Probe Form [If in doubt REJECT the candidate]
B4: Candidate Name: | E4: Interviewer Name: | H4: Interview Outcome: | M4: Architecture | N4: HTML/CSS | O4: JS | P4: Packaging | Q4: NFR | R4: SAL2Count | S4: SAL1Count | T4: Associate Count | U4: Rejected Count | V4: isRejected | W4: isSAL2 | X4: isSAL1 | Y4: isAL1 | Z4: isAL2 | AA4: Career Stage | AB4: HTML/CSS | AC4: NFR
B5: Total years of exp.: | E5: Interviewer OID: | H5: Selected for Level: | M5: =L13 -> No Experience | N5: =L20 -> Rejected | O5: =L27 -> Rejected | P5: =L35 -> - | Q5: =L38 -> No Experience | R5: =COUNTIF(M5:Q5,"SAL2") -> 0 | S5: =COUNTIF(M5:Q5,"SAL1")+COUNTIF(M5:Q5,"Sr Associate") -> 0 | T5: =COUNTIF(M5:P5,"Associate")+COUNTIF(M5:P5,"AL2")+COUNTIF(M5:P5,"AL1") -> 0 | U5: =COUNTIF(N5:O5,"REJECTED") -> 2 | V5: =U5>0 -> TRUE | W5: =AND(R5>=3,O5="SAL2",T5=0,NOT(V5)) -> FALSE | X5: =AND(OR(AND(O5="SAL1",N5<>"AL1",N5<>"AL2"),AND(O5="SAL2",N5<>"AL1")),NOT(V5),NOT(W5)) -> FALSE | Y5: =AND(N5="AL1",O5="Associate",Q5="No Experience",NOT(V5),NOT(W5),NOT(X5)) -> FALSE | Z5: =AND(NOT(V5),NOT(W5),NOT(X5),NOT(Y5)) -> FALSE | AA5: =IF(V5,"REJECTED",IF(W5,"Lead Experience Engineer",IF(X5,"Senior Experience Engineer",IF(Y5,"Experience Engineer L1",IF(Z5,"Experience Engineer L2","Thinking"))))) -> REJECTED | AB5: =OR(AND(AA5="AL2",N5="AL1"),AND(AA5="SAL1",N5="AL2"),AND(AA5="SAL2",N5="SAL1")) -> FALSE | AC5: =AND(NOT(V5),OR(Q5="No Experience",AND(OR(AA5="SAL1",AA5="SAL2"),Q5="Associate"))) -> FALSE
B6: Relevant years of exp.: | E6: (Rev)Shadow Name: | H6: Rejection Reason:
B7: Interviewed for: | E7: Recommended Title | F7: =AA5 -> REJECTED | H7: Sections to be trained on:
B8: Evaluation Date: | E8: Recommended Training | F8: =IF(AB5,IF(AC5,"HTML/CSS & NFR ","HTML/CSS"),IF(AC5,"NFR","No trainings required")) -> No trainings required
B9: Domain Feedback Summary & Key Highlights:
B10: Teachable Skill Gap Details:
B11: Choose hands-on exercise | C11: Pokemon 1 | D11: =IFERROR(VLOOKUP(C11,'Core Exercise'!A1:B8,2,FALSE),"Choose the exercise from left side column") -> Create a vanilla JS application that consumes the https://pokeapi.co/api/v2/pokemon/ API and displays a dropdown list of pokemons. When the user selects a pokemon from the dropdown, the application should make a second API call using the "url" returned in the first API call to fetch the pokemon's details, including its abilities, and display them on the page. Once the details are fetched, they should be cached and the application should not make another API call for that pokemon again.
B12: Skill | C12: Areas To Be Probed / Competency Definition | F12: Evaluated Proficiency Level | G12: Feedback Details
B13: ARCHITECTURE | I13: AVG %age SCORE: | J13: =AVERAGE(K14:K19)/3*100 -> 0 | L13: =IF(J13<10, "No Experience", "SAL2") -> No Experience
B14: Architecture | C14: Can explain the frontend architecture of their existing project. And aware of architectural patterns like: MicroFrontends, SPA/MPA, Web Components, 12 Factor, MicroServices, ModuleFederation | F14: Did not probe | K14: =VLOOKUP(F14,Data!$D$3:$G$7,4,FALSE) -> 0
C15: Is clear with reasons of tech stack decisions made | F15: Did not probe | K15: =VLOOKUP(F15,Data!$D$3:$G$7,4,FALSE) -> 0
C16: Awareness of Rendering Techniques: SSR/CSR/SSG/ISR/ESR/PWA | F16: Did not probe | K16: =VLOOKUP(F16,Data!$D$3:$G$7,4,FALSE) -> 0
C17: Able to give a comparitive PoV on design system, atomic design pattern and various CSS code organization techniques e.g. CSS modules, inline CSS, styled-components, emotion, etc. | F17: Did not probe | K17: =VLOOKUP(F17,Data!$D$3:$G$7,4,FALSE) -> 0
C18: Experience with setting up Design Systems. Atomic design concepts. Storybook implementation. Understands concept of Design Tokens. | F18: Did not probe | K18: =VLOOKUP(F18,Data!$D$3:$G$7,4,FALSE) -> 0
B19: PWA | C19: Able to explain browser caching through http headers (cache-control, etag) Able to explain browser caching using service workers and benefits over http caching Able to tell different caching strategies for service workers | F19: Did not probe | K19: =VLOOKUP(F19,Data!$D$3:$G$7,4,FALSE) -> 0
B20: Web Basics / HTML / CSS | I20: AVG %age SCORE: | J20: =AVERAGE(K21:K26)/3*100 -> 0 | L20: =IF(J20<30,"Rejected",IF(J20<40,"AL1",IF(J20<60,"AL2",IF(J20<70,"SAL1","SAL2")))) -> Rejected
B21: HTML | Templating | C21: Sementic HTML, DOM | F21: Did not probe | K21: =VLOOKUP(F21,Data!$F$3:$G$7,2,FALSE) -> 0
C22: Able to create Form in native HTML and submit without JS. Able to add validations to form. Knows how to use FormData API. | F22: Did not probe | K22: =VLOOKUP(F22,Data!$F$3:$G$7,2,FALSE) -> 0
C23: Able to explain browser side storage (cookies / localstorage / sessionstorage / indexeddb) | F23: Did not probe | K23: =VLOOKUP(F23,Data!$F$3:$G$7,2,FALSE) -> 0
B24: CSS / processors & Responsive | C24: Understands CSS Concepts like: CSSOM, Rules, Selectors and Property values, Cascading, Inheritance, Specificity | F24: Did not probe | K24: =VLOOKUP(F24,Data!$F$3:$G$7,2,FALSE) -> 0
C25: Responsive Design (Mobile and Desktop first), Media Queries. Responsive Images. Layout - [flex, grid, float], display, postitioning. | F25: Did not probe | K25: =VLOOKUP(F25,Data!$F$3:$G$7,2,FALSE) -> 0
C26: Preprocessors (SCSS/SASS) / Postprocessors (PostCSS), Frameworks (Tailwind, Chakra, Bootstrap), CSS-in-JS (Styled Components, Emotion, CSS Modules) | F26: Did not probe | K26: =VLOOKUP(F26,Data!$F$3:$G$7,2,FALSE) -> 0
B27: JavaScript / TypeScript (Cover maximum listed topics as hands-on coding exercise) | I27: AVG %age SCORE: | J27: =(SUM(K28:K34)/(5*3))*100 -> 0 | L27: =IF(J27<40,"Rejected",IF(J27<60,"Associate",IF(J27<70,"SAL1",IF(K31>=1,"SAL2","SAL1")))) -> Rejected
B28: Javascript | C28: Hands on coding exercise to cover following topics: Event Listeners (Able to use following: addEventListener, event object, stopPropagation, preventDefault) DOM Manipulation (querySelector, querySelectorAll, innerHTML, DOM Fragments[optional]) | F28: Did not probe | K28: =VLOOKUP(F28,Data!$F$3:$G$7,2,FALSE) -> 0
C29: Loops/map Promises (then-catch, async-await, promise.all) Fetch API Able to create modules, and use import and export statement Able to explain usecases for deboune and throttle Able to modify and transform objects | F29: Did not probe | K29: =VLOOKUP(F29,Data!$F$3:$G$7,2,FALSE) -> 0
C30: Is the code written well structured? - If code written in single file and poor variable names - No Experience - If code written in single file with good code breakdown - Awareness of concepts - If code written in multiple files with logic split across - Able to explain concepts in depth - If code written in multiple file with utilities, constants and config also managed separately - Confident with decision making and hands on | F30: Did not probe | K30: =VLOOKUP(F30,Data!$D$3:$G$7,4,FALSE) -> 0
C31: Has experience of writing Unit Test cases in previous projects using Jest/Karma/Jasmine/Mocha/Enzyme/RTL Has experience in writing functional test cases (not snapshot testing) Able to tell test cases to be written for a given scenario Able to explain HTTP API mocking and browser API methods mocking (e.g. mocking localstorage) | F31: Did not probe | K31: =VLOOKUP(F31,Data!$D$3:$G$7,4,FALSE) -> 0
B32: Typescript | C32: Able to explain the benefits and trade-offs of using TypeScript over JavaScript. Understands basic types, including string, number, boolean, undefined, null, and any. | F32: Did not probe | K32: =VLOOKUP(F32,Data!$F$3:$G$7,2,FALSE)/3 -> 0
C33: Comfortable with advanced types such as interfaces, enums, tuples, generics, and unions. | F33: Did not probe | K33: =VLOOKUP(F33,Data!$F$3:$G$7,2,FALSE)/3 -> 0
C34: Experience in using TypeScript with popular frontend frameworks, particularly React. Has experience configuring a TypeScript project using tsconfig.json. | F34: Did not probe | K34: =VLOOKUP(F34,Data!$D$3:$G$7,4,FALSE)/3 -> 0
B35: Tooling & Bundlers | I35: AVG %age SCORE: | J35: =AVERAGE(K36:K37)/3*100 -> 0 | L35: =IF(J35<30,"-","SAL2") -> -
B36: Bundlers | C36: Able to explain concept of Monorepo and related tools (nx, turborepo) Experience configuring a module bundler - webpack/esbuild/rollup/vite | F36: Did not probe | K36: =VLOOKUP(F36,Data!$D$3:$G$7,4,FALSE) -> 0
B37: Tooling | C37: Has experience of using & configuring following tools: Linters - Pa11y, ESLint, Sonar Formatters - Prettier GitHooks - Husky, lint-staged WebServers - Apache/Nginx | F37: Did not probe | K37: =VLOOKUP(F37,Data!$D$3:$G$7,4,FALSE) -> 0
B38: NFR's | I38: AVG %age SCORE: | J38: =AVERAGE(K39:K41)/3*100 -> 0 | L38: =IF(J38<10,"No Experience",IF(J38<20,"Associate","SAL2")) -> No Experience
B39: Performance | C39: Able to run any performance tool (e.g. lighthouse, webpagetest, pagespeed, sitespeed.io, etc) on a website and gather report Able to explain different performance metrices e.g. (WebVitals, Critical Rendering Path) Able to tell performance improvement areas and their impact on performance metrices like: Web Compression(gzip/brotli), Caching / CDN / Expirations, HTTP2, Service Workers | F39: Did not probe | K39: =VLOOKUP(F39,Data!$D$3:$G$7,4,FALSE) -> 0
B40: Security | C40: Able to explain security & compliance topics like: HIPPA, GDPR, PCI, PII, XSS, CORS, MITM, CSP, CSRF, OWASP, SSL/TLS Able to explain mechanism to secure cookies | F40: Did not probe | K40: =VLOOKUP(F40,Data!$D$3:$G$7,4,FALSE) -> 0
B41: Accessibility | C41: Understands accessibility guidelines like : A/AA/AAA/ADA/508 Able to explain use of aria live regions for dynamic content announcement Able to use any screen reader to access a website Able to create accessible forms and write code adhering to meet the accessibility benchmarks | F41: Did not probe | K41: =VLOOKUP(F41,Data!$D$3:$G$7,4,FALSE) -> 0
B42: Attributes
...

Sheet 2 - FW React
B2: Experience Engineering Hiring Probe Form [If in doubt REJECT the candidate]
B4: Candidate Name: | C4: John Doe | E4: Interviewer Name: | F4: Medha | H4: Interview Outcome: | I4: Rejected | M4: React Basics | N4: React Advance | O4: Node | P4: GraphQL | Q4: isRejected | R4: isSAL2 | S4: isSAL1 | T4: isAL1 | U4: isAL2 | V4: Career Stage | W4: React Specialist
B5: Total years of exp.: | C5: 3 | E5: Interviewer OID: | F5: AI-001 | H5: Selected for Level: | I5: REJECTED | M5: =L13 -> SAL1 | N5: =L21 -> SAL2 | O5: =L30 -> - | P5: =L37 -> - | Q5: =OR(M5="Rejected",N5="Rejected") -> FALSE | R5: =AND(NOT(Q5),M5="SAL2",N5<>"Associate") -> FALSE | S5: =AND(NOT(Q5),NOT(R5),OR(M5="SAL1",M5="SAL2"),OR(N5<>"Associate",AND(N5="Associate",OR(O5<>"-",P5<>"-")))) -> TRUE | T5: =AND(NOT(Q5),NOT(R5),NOT(S5),M5="Associate",N5="Associate",O5="-", P5="-") -> FALSE | U5: =AND(NOT(Q5),NOT(R5),NOT(S2),NOT(T2)) -> TRUE | V5: =IF(Q5,"REJECTED",IF(R5,"Lead Experience Engineer",IF(S5,"Senior Experience Engineer",IF(T5,"Experience Engineer L1",IF(U5,"Experience Engineer L2","Thinking"))))) -> Senior Experience Engineer | W5: =AND(V5="SAL1",F2="Associate") -> FALSE
B6: Relevant years of exp.: | C6: 3 | E6: (Rev)Shadow Name: | H6: Rejection Reason: | I6: Lacked Fundamentals
B7: Interviewed for: | C7: Senior Experience Engineer | E7: Recommended Title | F7: =V5 -> Senior Experience Engineer | H7: Sections to be trained on: | I7: React Basics, React Advanced, Node, GraphQL
B8: Evaluation Date: | C8: 05/30/2026 | E8: Recommended Training | F8: =IF(W5,"React Specialist", "No trainings required") -> No trainings required
B9: Domain Feedback Summary & Key Highlights: | D9: The candidate demonstrated awareness of basic React concepts like conditional rendering and styling approaches, but struggled to provide concrete examples or deep explanations. They mentioned using CSS Modules and styled-components but could not articulate trade-offs. For state management, they vaguely referenced Context API but lacked clarity on useReducer or performance considerations. The candidate had no experience with Node.js or GraphQL, and could not answer questions on those topics. Overall, the candidate lacks the depth and hands-on experience required for a Senior Experience Engineer role.
B10: Requires foundational training in React hooks, state management, Node.js, and GraphQL.
B11: Choose hands-on exercise | C11: Shopping Cart | D11: =IFERROR(VLOOKUP(C11,'React Exercise'!A1:B8,2,FALSE),"Choose the exercise from left side column") -> Create a React web application that consumes the https://fakestoreapi.com/carts/2 API and displays a list of products in the cart. For each product in the cart, the application should make an API call to fetch the product details using the ID returned in the cart API and display the product title, price, and image. Note: The https://fakestoreapi.com/products/:id: API returns details for a single product. You will need to make an API call for each product in the cart to fetch the product details.
B12: Skill | C12: Areas To Be Probed / Competency Definition | F12: Evaluated Proficiency Level | G12: Feedback Details
B13: React Basics (Cover maximum listed topics as hands-on coding exercise) | I13: AVG %age SCORE: | J13: =AVERAGE(K14:K20)/3*100 -> 76.190476 | L13: =IF(J13<60, "Rejected",IF(J13<70,"Associate",IF(J13<80,"SAL1","SAL2"))) -> SAL1
B14: React Basics | C14: Able to create nested components, and write clean JSX markup (and uses atomic design principle) Able to do conditional rendering Able to import & export components through different files (both default and named exports) | F14: Able to explain concepts theoritically | G14: Could not explain error boundaries or their limitations. | K14: =VLOOKUP(F14,Data!$F$3:$G$7,2,FALSE) -> 3
C15: Able to style the component using traditional css or css-in-js | F15: Able to explain concepts theoritically | K15: =VLOOKUP(F15,Data!$F$3:$G$7,2,FALSE) -> 3
C16: Able to demonstrate use of fragments, useEffect, useState | F16: Able to explain concepts theoritically | K16: =VLOOKUP(F16,Data!$F$3:$G$7,2,FALSE) -> 3
C17: Able to render a component in loop and understands best practices related to key attribute | F17: Able to explain concepts theoritically | K17: =VLOOKUP(F17,Data!$F$3:$G$7,2,FALSE) -> 3
C18: Able to create form and handle submitting data using Ajax Able to bind events to form submit and add validation to form fields | F18: Able to explain concepts theoritically | K18: =VLOOKUP(F18,Data!$F$3:$G$7,2,FALSE) -> 3
C19: Able to write functional unit test cases for react component using enzyme/RTL (not snapshot) | F19: No Experience | K19: =VLOOKUP(F19,Data!$F$3:$G$7,2,FALSE) -> 1
C20: Able to demonstrate handling error using error boundries | F20: No Experience | K20: =VLOOKUP(F20,Data!$F$3:$G$7,2,FALSE) -> 0
B21: React Advance (Cover maximum listed topics as hands-on coding exercise) | I21: AVG %age SCORE: | J21: =AVERAGE(K22:K29)/3*100 -> 62.5 | L21: =IF(J21<25,"Rejected",IF(J21<40, "Associate", IF(J21<50,"SAL1","SAL2"))) -> SAL2
B22: React Advanced | C22: Has worked with various rendering patterns in React and Next JS e.g. SSR, CSR, SSG, ISR and able to define them | F22: No Experience | G22: Knew about dotenv but no logging best practices. | K22: =VLOOKUP(F22,Data!$F$3:$G$7,2,FALSE) -> 1
C23: Able to explain and create react specific design patters e.g. Custom Hooks, Higher Order Components, Render Props, Compound Component, etc | F23: Able to explain concepts theoritically | K23: =VLOOKUP(F23,Data!$F$3:$G$7,2,FALSE) -> 1
C24: Able to explain usecases for using Context API and how to use it with useReducer pattern | F24: Able to explain concepts theoritically | K24: =VLOOKUP(F24,Data!$F$3:$G$7,2,FALSE) -> 3
C25: Able to define purpose of useRef with real life use cases and best practices | F25: Able to explain concepts theoritically | K25: =VLOOKUP(F25,Data!$F$3:$G$7,2,FALSE) -> 3
C26: Able to demonstrate memoization in react using useMemo and useCallback and explain different use cases for each of them | F26: Able to explain concepts theoritically | K26: =VLOOKUP(F26,Data!$F$3:$G$7,2,FALSE) -> 3
C27: Able to explain react routing/next routing Able to explain route based chunking, react lazy and suspense Able to give PoV on SPA and MPA | F27: No Experience | K27: =VLOOKUP(F27,Data!$F$3:$G$7,2,FALSE) -> 0
C28: Able to give PoV on various state management techniques e.g. Redux, redux toolkit, react-query, recoil, jotai, context api, xstate, Apollo Client, etc. Able to give explain handling of side-effects with state management library (e.g. redux thunk, saga, etc) | F28: Able to explain concepts theoritically | K28: =VLOOKUP(F28,Data!$F$3:$G$7,2,FALSE) -> 1
C29: Understands public and private npm registry and publishing of packages Able to explain using environment variables using dotenv module Able to explain importance of logging in server application, and best practices around logging like log levels and log redaction | F29: Able to explain concepts theoritically | K29: =VLOOKUP(F29,Data!$F$3:$G$7,2,FALSE) -> 3
B30: Node | I30: AVG %age SCORE: | J30: =AVERAGE(K31:K36)/3*100 -> 0 | L30: =IF(J30<5,"-",IF(J30<10,"AL2","Sr Associate")) -> -
B31: Node JS | C31: Has implemented and able to explain architectural concepts like - MicroServices, 12 factor, Monolith, Serverless, Domain Driven Design | F31: No Experience | G31: Could not compare Node.js frameworks. | K31: =VLOOKUP(F31,Data!$D$3:$G$7,4,FALSE) -> 0
C32: - Able to create a basic HTTP server - Understands request & response objects & headers - Understands different HTTP verbs like GET, POST, DELETE, PUT etc - Understands commonly used HTTP response codes (2xx, 3xx, 4xx, 5xx) - Understands Error & Exception Handling with HTTP Server | F32: No Experience | K32: =VLOOKUP(F32,Data!$D$3:$G$7,4,FALSE) -> 0
C33: - Able to create a RESTful API and explain RESTful principles - Experience working with API documentation/testing tools like swagger, openAPI, PostMan | F33: No Experience | K33: =VLOOKUP(F33,Data!$D$3:$G$7,4,FALSE) -> 0
C34: Has worked upon and able to explain about streaming architecture solutions like WebSockets, Server Sent Events and its use cases | F34: No Experience | K34: =VLOOKUP(F34,Data!$D$3:$G$7,4,FALSE) -> 0
C35: - Able to give PoV on Relational vs Non-Relational DBs - Explain the importance of ORM and give examples of node based ORMs - Understands DB concepts like CAP theorem, ACID compliance, Sharding, Replication - Experience working with in Memory Datastores - Redis, Memcached, Couchbase, etc | F35: No Experience | K35: =VLOOKUP(F35,Data!$D$3:$G$7,4,FALSE) -> 0
C36: - Understands difference between commonjs and ejs module systems - Has worked on a node based API framework like fastify, koa, express, Hapi, nest.js | F36: No Experience | K36: =VLOOKUP(F36,Data!$D$3:$G$7,4,FALSE) -> 0
B37: GraphQL | I37: AVG %age SCORE: | J37: =AVERAGE(K38:K50)/3*100 -> 0 | L37: =IF(J37<5,"-",IF(J37<10,"AL2","Sr Associate")) -> -
B38: GraphQL | C38: - Able to explain benefits and challenges with GraphQL implementation - Has experience creating GraphQL API server - e.g. Apollo GraphQL, Apollo Federation, AWS AppSync, Hasura, Prisma | F38: No Experience | G38: No experience with GraphQL clients. | K38: =VLOOKUP(F38,Data!$D$3:$G$7,4,FALSE) -> 0
C39: Able to present POV on caching challenges and strategies with GraphQL | F39: No Experience | K39: =VLOOKUP(F39,Data!$D$3:$G$7,4,FALSE) -> 0
C40: Able to explain concepts like batching, introspection and scalar types (Int, Float, Boolean, String, ID) in GraphQL | F40: No Experience | K40: =VLOOKUP(F40,Data!$D$3:$G$7,4,FALSE) -> 0
C41: Able to explain error handling and arguments handling in GraphQL | F41: No Experience | K41: =VLOOKUP(F41,Data!$D$3:$G$7,4,FALSE) -> 0
C42: - Able to write schema and resolvers in GraphQL - Able to work with GraphQL Playground | F42: No Experience | K42: =VLOOKUP(F42,Data!$D$3:$G$7,4,FALSE) -> 0
...

Sheet Data
B2: Career Stage | C2: Interview Outcome | D2: Scoring Architecture | E2: Rejection Reason | F2: Scoring Development | G2: Scoring Score | H2: Core XT Training Sections | I2: Will You Take Person | J2: React Training Sections
B3: Experience Engineer L1 | C3: Selected | D3: Did not probe | E3: Lacked Fundamentals | F3: Did not probe | G3: 0 | H3: HTML/CSS | I3: Yes | J3: React Specialist
B4: Experience Engineer L2 | C4: Rejected | D4: No Experience | E4: No Hands on Experience | F4: No Experience | G4: 0 | H4: NFR | I4: No
B5: Senior Experience Engineer | C5: Needs Another Round | D5: Awareness of concepts | E5: Gaps in multiple categories | F5: Able to explain concepts theoritically | G5: 1 | H5: HTML/CSS & NFR
B6: Lead Experience Engineer | D6: Able to explain concepts in depth | F6: Able to code with guidance | G6: 2
B7: Manager Experience Engineering | D7: Confident with decision making & hands on | F7: Confident hands on developer | G7: 3

Sheet React Exercise
A1: React
A2: Pokemon 1 | B2: Create a React web application that consumes the https://pokeapi.co/api/v2/pokemon/ API and displays a dropdown list of pokemons. When the user selects a pokemon from the dropdown, the application should make a second API call using the "url" returned in the first API call to fetch the pokemon's details, including its abilities, and display them on the page. Once the details are fetched, they should be cached and the application should not make another API call for that pokemon again.
A3: Pokemon 2 | B3: Create a React web application that consumes the https://pokeapi.co/api/v2/pokemon/ API and displays a table containing a list of pokemon names and their abilities. The application should make multiple parallel API calls to fetch the pokemon details, including their abilities, and display them in the table.
A4: Starwars 1 | B4: Create a React web application that consumes the https://swapi.dev/api/people/ API and displays a dropdown containing a list of Star Wars characters. When a user selects a character from the dropdown, the application should make an API call to fetch the films the character has appeared in and the vehicles they have used, and display them in a table.
A5: Starwars 2 | B5: Create a React web application that consumes the https://swapi.dev/api/people/ API and displays a table containing a list of Star Wars characters and the films they have appeared in and the vehicles they have used. The application should make multiple parallel API calls to fetch the film and vehicle details using the URLs returned in the first API call and display them in the table.
A6: Shopping Cart | B6: Create a React web application that consumes the https://fakestoreapi.com/carts/2 API and displays a list of products in the cart. For each product in the cart, the application should make an API call to fetch the product details using the ID returned in the cart API and display the product title, price, and image. Note: The https://fakestoreapi.com/products/:id: API returns details for a single product. You will need to make an API call for each product in the cart to fetch the product details.
A7: Product Listing Page | B7: Create a React web application that consumes the https://fakestoreapi.com/products?sort=asc API and displays a list of products in ascending order based on price. The application should also include a dropdown to allow the user to change the sorting of the products between ascending and descending. When the user changes the sorting order, the application should update the query parameter value and fetch the products with the new sorting order.
A8: Custom | B8: Describe the problem statement asked

Sheet Core Exercise
A1: Core
A2: Pokemon 1 | B2: Create a vanilla JS application that consumes the https://pokeapi.co/api/v2/pokemon/ API and displays a dropdown list of pokemons. When the user selects a pokemon from the dropdown, the application should make a second API call using the "url" returned in the first API call to fetch the pokemon's details, including its abilities, and display them on the page. Once the details are fetched, they should be cached and the application should not make another API call for that pokemon again.
A3: Pokemon 2 | B3: Create a vanilla js application that consumes the https://pokeapi.co/api/v2/pokemon/ API and displays a table containing a list of pokemon names and their abilities. The application should make multiple parallel API calls to fetch the pokemon details, including their abilities, and display them in the table.
A4: Starwars 1 | B4: Create a vanilla js application that consumes the https://swapi.dev/api/people/ API and displays a dropdown containing a list of Star Wars characters. When a user selects a character from the dropdown, the application should make an API call to fetch the films the character has appeared in and the vehicles they have used, and display them in a table.
A5: Starwars 2 | B5: Create a vanilla js application that consumes the https://swapi.dev/api/people/ API and displays a table containing a list of Star Wars characters and the films they have appeared in and the vehicles they have used. The application should make multiple parallel API calls to fetch the film and vehicle details using the URLs returned in the first API call and display them in the table.
A6: Shopping Cart | B6: Create a vanilla js application that consumes the https://fakestoreapi.com/carts/2 API and displays a list of products in the cart. For each product in the cart, the application should make an API call to fetch the product details using the ID returned in the cart API and display the product title, price, and image. Note: The https://fakestoreapi.com/products/:id: API returns details for a single product. You will need to make an API call for each product in the cart to fetch the product details.
A7: Product Listing Page | B7: Create a vanilla js application that consumes the https://fakestoreapi.com/products?sort=asc API and displays a list of products in ascending order based on price. The application should also include a dropdown to allow the user to change the sorting of the products between ascending and descending. When the user changes the sorting order, the application should update the query parameter value and fetch the products with the new sorting order.
A8: Custom | B8: Describe the problem statement asked

Sheet _meta
A1: app | B1: interviewly
A2: version | B2: 0.1.0
A3: model_provider | B3: deepseek
A4: model_id | B4: deepseek-v4-flash
A5: generated_at | B5: 2026-05-29T20:01:56.400Z
A6: meeting_id | B6: MSoyMGYzNjNhYy0xZWFjLTRhMjQtOTNkNy1iZTIwNDBhMmVmNzAqMCoqMTk6bWVldGluZ19aamhoTldRd00ySXRaakExWWkwMFpHVmpMVGd4Wm1RdE5EYzJPVFZrWkdJd09XTXhAdGhyZWFkLnYy
A7: transcript_sha256 | B7: 455d04c9692aa16b9b0a21c9ae501c83c5b3e6b599703d8195db78cab349f6eb
A8: recruiter_email | B8: SiddharthaChatterjee@RecipeBari.onmicrosoft.com
A9: bot_user_email | B9: interviewly.bot@RecipeBari.onmicrosoft.com
A10: test_mode | B10: false
A11: fixture_id
