Workbook
Name Career_Stage: Data!$B$3:$B$7
Name Core_Exercise: 'Core Exercise'!$A$2:$A$8
Name Core_XT_Training_Sections: Data!$H$3:$H$5
Name Interview_Outcome: Data!$C$3:$C$5
Name React_Exercise: 'React Exercise'!$A$2:$A$8
Name React_Training_Sections: Data!$J$3
Name Rejection_Reason: Data!$E$3:$E$5
Name Scoring_Architecture: Data!$D$3:$D$7
Name Scoring_Development: Data!$F$3:$F$7
Name Will_You_Take_Person: Data!$I$3:$I$4

Sheet 1 - HTML, CSS & NFRs
B2: Experience Engineering Hiring Probe Form [If in doubt REJECT the candidate]
B4: Candidate Name: | C4: Schema Smoke Candidate | E4: Interviewer Name: | F4: Medha | H4: Interview Outcome: | I4: Selected | M4: Architecture | N4: HTML/CSS | O4: JS | P4: Packaging | Q4: NFR | R4: SAL2Count | S4: SAL1Count | T4: Associate Count | U4: Rejected Count | V4: isRejected | W4: isSAL2 | X4: isSAL1 | Y4: isAL1 | Z4: isAL2 | AA4: Career Stage | AB4: HTML/CSS | AC4: NFR
B5: Total years of exp.: | C5: 7 | E5: Interviewer OID: | F5: AI-001 | H5: Selected for Level: | I5: Senior Experience Engineer | M5: =L13 -> No Experience | N5: =L20 -> Rejected | O5: =L27 -> Rejected | P5: =L35 -> - | Q5: =L38 -> No Experience | R5: =COUNTIF(M5:Q5,"SAL2") -> 0 | S5: =COUNTIF(M5:Q5,"SAL1")+COUNTIF(M5:Q5,"Sr Associate") -> 0 | T5: =COUNTIF(M5:P5,"Associate")+COUNTIF(M5:P5,"AL2")+COUNTIF(M5:P5,"AL1") -> 0 | U5: =COUNTIF(N5:O5,"REJECTED") -> 2 | V5: =U5>0 -> TRUE | W5: =AND(R5>=3,O5="SAL2",T5=0,NOT(V5)) -> FALSE | X5: =AND(OR(AND(O5="SAL1",N5<>"AL1",N5<>"AL2"),AND(O5="SAL2",N5<>"AL1")),NOT(V5),NOT(W5)) -> FALSE | Y5: =AND(N5="AL1",O5="Associate",Q5="No Experience",NOT(V5),NOT(W5),NOT(X5)) -> FALSE | Z5: =AND(NOT(V5),NOT(W5),NOT(X5),NOT(Y5)) -> FALSE | AA5: =IF(V5,"REJECTED",IF(W5,"Lead Experience Engineer",IF(X5,"Senior Experience Engineer",IF(Y5,"Experience Engineer L1",IF(Z5,"Experience Engineer L2","Thinking"))))) -> REJECTED | AB5: =OR(AND(AA5="AL2",N5="AL1"),AND(AA5="SAL1",N5="AL2"),AND(AA5="SAL2",N5="SAL1")) -> FALSE | AC5: =AND(NOT(V5),OR(Q5="No Experience",AND(OR(AA5="SAL1",AA5="SAL2"),Q5="Associate"))) -> FALSE
B6: Relevant years of exp.: | C6: 5 | E6: (Rev)Shadow Name: | H6: Rejection Reason:
B7: Interviewed for: | C7: Senior Experience Engineer | E7: Recommended Title | F7: =AA5 -> REJECTED | H7: Sections to be trained on:
B8: Evaluation Date: | C8: 05/27/2026 | E8: Recommended Training | F8: =IF(AB5,IF(AC5,"HTML/CSS & NFR ","HTML/CSS"),IF(AC5,"NFR","No trainings required")) -> No trainings required
B9: Domain Feedback Summary & Key Highlights: | D9: Synthetic domain feedback summary written by scripts/smoke-react-probeform.ts. Confirms D10 wiring on the React role schema. All competency rows below were filled deterministically without an LLM call.
B10: Teachable Skill Gap Details:
B11: Choose hands-on exercise | C11: Pokemon 1 | D11: =IFERROR(VLOOKUP(C11,'Core Exercise'!A1:B8,2,FALSE),"Choose the exercise from left side column") -> Create a vanilla JS application that consumes the https://pokeapi.co/api/v2/pokemon/ API and displays a dropdown list of pokemons. When the user selects a pokemon from the dropdown, the application should make a second API call using the "url" returned in the first API call to fetch the pokemon's details, including its abilities, and display them on the page. Once the details are fetched, they should be cached and the application should not make another API call for that pokemon again.
B12: Skill | C12: Areas To Be Probed / Competency Definition | F12: Evaluated Proficiency Level | G12: Feedback Details
B13: ARCHITECTURE | I13: AVG %age SCORE: | J13: =AVERAGE(K14:K19)/3*100 -> 0 | L13: =IF(J13<10, "No Experience", "SAL2") -> No Experience
B14: Architecture | C14: Can explain the frontend architecture of their existing project. And aware of architectural patterns like: MicroFrontends, SPA/MPA, Web Components, 12 Factor, MicroServices, ModuleFederation | F14: Able to explain concepts in depth | G14: [HTML & Accessibility] Smoke test feedback for row 18 — Forms — validation, error messages, aria-invalid, aria-describedby. | K14: =VLOOKUP(F14,Data!$D$3:$G$7,4,FALSE) -> 0
C15: Is clear with reasons of tech stack decisions made | F15: Confident hands on developer | K15: =VLOOKUP(F15,Data!$D$3:$G$7,4,FALSE) -> 0
C16: Awareness of Rendering Techniques: SSR/CSR/SSG/ISR/ESR/PWA | F16: Confident hands on developer | K16: =VLOOKUP(F16,Data!$D$3:$G$7,4,FALSE) -> 0
C17: Able to give a comparitive PoV on design system, atomic design pattern and various CSS code organization techniques e.g. CSS modules, inline CSS, styled-components, emotion, etc. | F17: Confident hands on developer | K17: =VLOOKUP(F17,Data!$D$3:$G$7,4,FALSE) -> 0
C18: Experience with setting up Design Systems. Atomic design concepts. Storybook implementation. Understands concept of Design Tokens. | F18: Confident hands on developer | K18: =VLOOKUP(F18,Data!$D$3:$G$7,4,FALSE) -> 0
B19: PWA | C19: Able to explain browser caching through http headers (cache-control, etag) Able to explain browser caching using service workers and benefits over http caching Able to tell different caching strategies for service workers | F19: Able to explain concepts in depth | G19: [HTML & Accessibility] Smoke test feedback for row 19 — SEO — meta tags, Open Graph, structured data (JSON-LD). | K19: =VLOOKUP(F19,Data!$D$3:$G$7,4,FALSE) -> 0
B20: Able to explain concepts in depth | G20: [HTML & Accessibility] Smoke test feedback for row 20 — Security — CSP, CSRF tokens, XSS prevention. | I20: AVG %age SCORE: | J20: =AVERAGE(K21:K26)/3*100 -> 0 | L20: =IF(J20<30,"Rejected",IF(J20<40,"AL1",IF(J20<60,"AL2",IF(J20<70,"SAL1","SAL2")))) -> Rejected
B21: HTML | Templating | C21: Sementic HTML, DOM | F21: Did not probe | G21: [CSS & Layout] Smoke test feedback for row 23 — Flexbox — alignment, wrapping, order, flex shorthand. | K21: =VLOOKUP(F21,Data!$F$3:$G$7,2,FALSE) -> 0
C22: Able to create Form in native HTML and submit without JS. Able to add validations to form. Knows how to use FormData API. | F22: Confident hands on developer | K22: =VLOOKUP(F22,Data!$F$3:$G$7,2,FALSE) -> 0
C23: Able to explain browser side storage (cookies / localstorage / sessionstorage / indexeddb) | F23: Confident hands on developer | K23: =VLOOKUP(F23,Data!$F$3:$G$7,2,FALSE) -> 0
B24: CSS / processors & Responsive | C24: Understands CSS Concepts like: CSSOM, Rules, Selectors and Property values, Cascading, Inheritance, Specificity | F24: Confident hands on developer | G24: [CSS & Layout] Smoke test feedback for row 26 — CSS layers — @layer, cascade control, specificity management. | K24: =VLOOKUP(F24,Data!$F$3:$G$7,2,FALSE) -> 0
C25: Responsive Design (Mobile and Desktop first), Media Queries. Responsive Images. Layout - [flex, grid, float], display, postitioning. | F25: Confident hands on developer | K25: =VLOOKUP(F25,Data!$F$3:$G$7,2,FALSE) -> 0
C26: Preprocessors (SCSS/SASS) / Postprocessors (PostCSS), Frameworks (Tailwind, Chakra, Bootstrap), CSS-in-JS (Styled Components, Emotion, CSS Modules) | F26: Able to explain concepts in depth | K26: =VLOOKUP(F26,Data!$F$3:$G$7,2,FALSE) -> 0
B27: Able to explain concepts in depth | G27: [CSS & Layout] Smoke test feedback for row 27 — CSS architecture — BEM, CUBE, naming conventions. | I27: AVG %age SCORE: | J27: =(SUM(K28:K34)/(5*3))*100 -> 0 | L27: =IF(J27<40,"Rejected",IF(J27<60,"Associate",IF(J27<70,"SAL1",IF(K31>=1,"SAL2","SAL1")))) -> Rejected
B28: Javascript | C28: Hands on coding exercise to cover following topics: Event Listeners (Able to use following: addEventListener, event object, stopPropagation, preventDefault) DOM Manipulation (querySelector, querySelectorAll, innerHTML, DOM Fragments[optional]) | F28: Able to explain concepts in depth | G28: [CSS & Layout] Smoke test feedback for row 29 — Rendering pipeline — CSSOM, layout, paint, compositing. | K28: =VLOOKUP(F28,Data!$F$3:$G$7,2,FALSE) -> 0
C29: Loops/map Promises (then-catch, async-await, promise.all) Fetch API Able to create modules, and use import and export statement Able to explain usecases for deboune and throttle Able to modify and transform objects | F29: Able to explain concepts in depth | K29: =VLOOKUP(F29,Data!$F$3:$G$7,2,FALSE) -> 0
C30: Is the code written well structured? - If code written in single file and poor variable names - No Experience - If code written in single file with good code breakdown - Awareness of concepts - If code written in multiple files with logic split across - Able to explain concepts in depth - If code written in multiple file with utilities, constants and config also managed separately - Confident with decision making and hands on | F30: Did not probe | K30: =VLOOKUP(F30,Data!$D$3:$G$7,4,FALSE) -> 0
C31: Has experience of writing Unit Test cases in previous projects using Jest/Karma/Jasmine/Mocha/Enzyme/RTL Has experience in writing functional test cases (not snapshot testing) Able to tell test cases to be written for a given scenario Able to explain HTTP API mocking and browser API methods mocking (e.g. mocking localstorage) | F31: Confident hands on developer | G31: [JavaScript & TypeScript] Smoke test feedback for row 31 — ES2023 — array findLast, toSorted, toReversed, with. | K31: =VLOOKUP(F31,Data!$D$3:$G$7,4,FALSE) -> 0
B32: Typescript | C32: Able to explain the benefits and trade-offs of using TypeScript over JavaScript. Understands basic types, including string, number, boolean, undefined, null, and any. | F32: Confident hands on developer | G32: [JavaScript & TypeScript] Smoke test feedback for row 32 — Modules — import/export, dynamic import, tree shaking. | K32: =VLOOKUP(F32,Data!$F$3:$G$7,2,FALSE)/3 -> 0
C33: Comfortable with advanced types such as interfaces, enums, tuples, generics, and unions. | F33: Confident hands on developer | G33: [JavaScript & TypeScript] Smoke test feedback for row 33 — Async iterators — for await...of, async generators. | K33: =VLOOKUP(F33,Data!$F$3:$G$7,2,FALSE)/3 -> 0
C34: Experience in using TypeScript with popular frontend frameworks, particularly React. Has experience configuring a TypeScript project using tsconfig.json. | F34: Able to explain concepts in depth | G34: [JavaScript & TypeScript] Smoke test feedback for row 34 — Event loop — microtasks vs macrotasks, requestAnimationFrame. | K34: =VLOOKUP(F34,Data!$D$3:$G$7,4,FALSE)/3 -> 0
B35: Confident hands on developer | G35: [JavaScript & TypeScript] Smoke test feedback for row 35 — TypeScript — utility types, generics, type guards. | I35: AVG %age SCORE: | J35: =AVERAGE(K36:K37)/3*100 -> 0 | L35: =IF(J35<30,"-","SAL2") -> -
B36: Bundlers | C36: Able to explain concept of Monorepo and related tools (nx, turborepo) Experience configuring a module bundler - webpack/esbuild/rollup/vite | F36: Able to explain concepts in depth | G36: [JavaScript & TypeScript] Smoke test feedback for row 36 — Polyfills — core-js, transpilation, browser support strategies. | K36: =VLOOKUP(F36,Data!$D$3:$G$7,4,FALSE) -> 0
B37: Tooling | C37: Has experience of using & configuring following tools: Linters - Pa11y, ESLint, Sonar Formatters - Prettier GitHooks - Husky, lint-staged WebServers - Apache/Nginx | F37: Did not probe | K37: =VLOOKUP(F37,Data!$D$3:$G$7,4,FALSE) -> 0
B38: Able to explain concepts in depth | G38: [Performance & PWA] Smoke test feedback for row 38 — Core Web Vitals — LCP, FID/INP, CLS measurement + optimization. | I38: AVG %age SCORE: | J38: =AVERAGE(K39:K41)/3*100 -> 0 | L38: =IF(J38<10,"No Experience",IF(J38<20,"Associate","SAL2")) -> No Experience
B39: Performance | C39: Able to run any performance tool (e.g. lighthouse, webpagetest, pagespeed, sitespeed.io, etc) on a website and gather report Able to explain different performance metrices e.g. (WebVitals, Critical Rendering Path) Able to tell performance improvement areas and their impact on performance metrices like: Web Compression(gzip/brotli), Caching / CDN / Expirations, HTTP2, Service Workers | F39: Confident hands on developer | G39: [Performance & PWA] Smoke test feedback for row 39 — Service workers — install, activate, fetch, cache strategies. | K39: =VLOOKUP(F39,Data!$D$3:$G$7,4,FALSE) -> 0
B40: Security | C40: Able to explain security & compliance topics like: HIPPA, GDPR, PCI, PII, XSS, CORS, MITM, CSP, CSRF, OWASP, SSL/TLS Able to explain mechanism to secure cookies | F40: Able to explain concepts in depth | G40: [Performance & PWA] Smoke test feedback for row 40 — PWA — manifest, offline support, push notifications. | K40: =VLOOKUP(F40,Data!$D$3:$G$7,4,FALSE) -> 0
B41: Accessibility | C41: Understands accessibility guidelines like : A/AA/AAA/ADA/508 Able to explain use of aria live regions for dynamic content announcement Able to use any screen reader to access a website Able to create accessible forms and write code adhering to meet the accessibility benchmarks | F41: Confident hands on developer | G41: [Performance & PWA] Smoke test feedback for row 41 — Build tools — Vite config, HMR, code splitting. | K41: =VLOOKUP(F41,Data!$D$3:$G$7,4,FALSE) -> 0
B42: [Performance & PWA] Smoke test feedback for row 42 — Performance optimization — lazy loading, critical CSS, image optimization.
...

Sheet Data
B2: Career Stage | C2: Interview Outcome | D2: Scoring Architecture | E2: Rejection Reason | F2: Scoring Development | G2: Scoring Score | H2: Core XT Training Sections | I2: Will You Take Person | J2: React Training Sections
B3: Experience Engineer L1 | C3: Selected | D3: Did not probe | E3: Lacked Fundamentals | F3: Did not probe | G3: 0 | H3: HTML/CSS | I3: Yes | J3: React Specialist
B4: Experience Engineer L2 | C4: Rejected | D4: No Experience | E4: No Hands on Experience | F4: No Experience | G4: 0 | H4: NFR | I4: No
B5: Senior Experience Engineer | C5: Needs Another Round | D5: Awareness of concepts | E5: Gaps in multiple categories | F5: Able to explain concepts theoritically | G5: 1 | H5: HTML/CSS & NFR
B6: Lead Experience Engineer | D6: Able to explain concepts in depth | F6: Able to code with guidance | G6: 2
B7: Manager Experience Engineering | D7: Confident with decision making & hands on | F7: Confident hands on developer | G7: 3

Sheet _meta
A1: app | B1: interviewly
A2: version | B2: 0.1.0
A3: model_provider | B3: deepseek
A4: model_id | B4: deepseek-v4-flash
A5: generated_at | B5: 2026-05-30T20:08:04.597Z
A6: meeting_id | B6: smoke-react-probeform
A7: transcript_sha256 | B7: 0000000000000000000000000000000000000000000000000000000000000000
A8: recruiter_email | B8: smoke@example.com
A9: bot_user_email | B9: bot@example.com
A10: test_mode | B10: false
A11: fixture_id
