Workbook
Name Career_Stage: Data!$B$3:$B$7
Name Core_Exercise: 'Core Exercise'!$A$2:$A$8
Name Core_XT_Training_Sections: Data!$H$3:$H$5
Name Interview_Outcome: Data!$C$3:$C$5
Name React_Exercise: 'React Exercise'!$A$2:$A$8
Name React_Training_Sections: Data!$J$3
Name Rejection_Reason: Data!$E$3:$E$5
Name Scoring_Architecture: Data!$D$3:$D$7
Name Scoring_Development: Data!$F$3:$F$7
Name Will_You_Take_Person: Data!$I$3:$I$4

Sheet 2 - Java Backend
B2: Experience Engineering Hiring Probe Form [If in doubt REJECT the candidate]
B4: Candidate Name: | C4: Schema Smoke Candidate | E4: Interviewer Name: | F4: Medha | H4: Interview Outcome: | I4: Selected | M4: React Basics | N4: React Advance | O4: Node | P4: GraphQL | Q4: isRejected | R4: isSAL2 | S4: isSAL1 | T4: isAL1 | U4: isAL2 | V4: Career Stage | W4: React Specialist
B5: Total years of exp.: | C5: 7 | E5: Interviewer OID: | F5: AI-001 | H5: Selected for Level: | I5: Senior Experience Engineer | M5: =L13 -> SAL1 | N5: =L21 -> SAL2 | O5: =L30 -> - | P5: =L37 -> - | Q5: =OR(M5="Rejected",N5="Rejected") -> FALSE | R5: =AND(NOT(Q5),M5="SAL2",N5<>"Associate") -> FALSE | S5: =AND(NOT(Q5),NOT(R5),OR(M5="SAL1",M5="SAL2"),OR(N5<>"Associate",AND(N5="Associate",OR(O5<>"-",P5<>"-")))) -> TRUE | T5: =AND(NOT(Q5),NOT(R5),NOT(S5),M5="Associate",N5="Associate",O5="-", P5="-") -> FALSE | U5: =AND(NOT(Q5),NOT(R5),NOT(S2),NOT(T2)) -> TRUE | V5: =IF(Q5,"REJECTED",IF(R5,"Lead Experience Engineer",IF(S5,"Senior Experience Engineer",IF(T5,"Experience Engineer L1",IF(U5,"Experience Engineer L2","Thinking"))))) -> Senior Experience Engineer | W5: =AND(V5="SAL1",F2="Associate") -> FALSE
B6: Relevant years of exp.: | C6: 5 | E6: (Rev)Shadow Name: | H6: Rejection Reason:
B7: Interviewed for: | C7: Senior Experience Engineer | E7: Recommended Title | F7: =V5 -> Senior Experience Engineer | H7: Sections to be trained on:
B8: Evaluation Date: | C8: 05/27/2026 | E8: Recommended Training | F8: =IF(W5,"React Specialist", "No trainings required") -> No trainings required
B9: Domain Feedback Summary & Key Highlights: | D9: Synthetic domain feedback summary written by scripts/smoke-react-probeform.ts. Confirms D10 wiring on the React role schema. All competency rows below were filled deterministically without an LLM call.
B10: Teachable Skill Gap Details:
B11: Choose hands-on exercise | C11: Shopping Cart | D11: =IFERROR(VLOOKUP(C11,'React Exercise'!A1:B8,2,FALSE),"Choose the exercise from left side column") -> Create a React web application that consumes the https://fakestoreapi.com/carts/2 API and displays a list of products in the cart. For each product in the cart, the application should make an API call to fetch the product details using the ID returned in the cart API and display the product title, price, and image. Note: The https://fakestoreapi.com/products/:id: API returns details for a single product. You will need to make an API call for each product in the cart to fetch the product details.
B12: Skill | C12: Areas To Be Probed / Competency Definition | F12: Evaluated Proficiency Level | G12: Feedback Details
B13: React Basics (Cover maximum listed topics as hands-on coding exercise) | I13: AVG %age SCORE: | J13: =AVERAGE(K14:K20)/3*100 -> 76.190476 | L13: =IF(J13<60, "Rejected",IF(J13<70,"Associate",IF(J13<80,"SAL1","SAL2"))) -> SAL1
B14: Spring Boot & Autoconfiguration | C14: Spring Boot — @ConditionalOnClass / @ConditionalOnProperty | F14: Able to explain concepts in depth | G14: [Spring Boot & Autoconfiguration] Smoke test feedback for row 20 — Spring Boot — spring.factories / auto-configuration imports. | K14: =VLOOKUP(F14,Data!$F$3:$G$7,2,FALSE) -> 3
C15: Spring Boot — auto-configuration ordering / overriding | F15: Able to explain concepts in depth | K15: =VLOOKUP(F15,Data!$F$3:$G$7,2,FALSE) -> 3
C16: Spring Boot — embedded Tomcat vs Undertow vs Netty | F16: Able to explain concepts in depth | K16: =VLOOKUP(F16,Data!$F$3:$G$7,2,FALSE) -> 3
C17: Spring Boot — actuator endpoints / health indicators | F17: Confident hands on developer | K17: =VLOOKUP(F17,Data!$F$3:$G$7,2,FALSE) -> 3
C18: Spring Boot — @ConfigurationProperties vs @Value | F18: Confident hands on developer | K18: =VLOOKUP(F18,Data!$F$3:$G$7,2,FALSE) -> 3
C19: Spring Boot — profile-specific configuration / YAML multi-document | F19: Confident hands on developer | K19: =VLOOKUP(F19,Data!$F$3:$G$7,2,FALSE) -> 1
C20: Spring Boot — spring.factories / auto-configuration imports | F20: Able to explain concepts in depth | K20: =VLOOKUP(F20,Data!$F$3:$G$7,2,FALSE) -> 0
I21: AVG %age SCORE: | J21: =AVERAGE(K22:K29)/3*100 -> 62.5 | L21: =IF(J21<25,"Rejected",IF(J21<40, "Associate", IF(J21<50,"SAL1","SAL2"))) -> SAL2
B22: Spring Data JPA & Hibernate | C22: JPA — N+1 query detection / @EntityGraph | F22: Confident hands on developer | G22: [Spring Data JPA & Hibernate] Smoke test feedback for row 29 — Spring Data JPA — Specification / QueryDSL. | K22: =VLOOKUP(F22,Data!$F$3:$G$7,2,FALSE) -> 1
C23: Hibernate — first-level vs second-level cache | F23: Able to explain concepts in depth | K23: =VLOOKUP(F23,Data!$F$3:$G$7,2,FALSE) -> 1
C24: JPA — @OneToMany fetch strategies (LAZY vs EAGER) | F24: Confident hands on developer | K24: =VLOOKUP(F24,Data!$F$3:$G$7,2,FALSE) -> 3
C25: Hibernate — batch fetching / @BatchSize | F25: Confident hands on developer | K25: =VLOOKUP(F25,Data!$F$3:$G$7,2,FALSE) -> 3
C26: Spring Data JPA — derived query methods vs @Query | F26: Confident hands on developer | K26: =VLOOKUP(F26,Data!$F$3:$G$7,2,FALSE) -> 3
C27: JPA — optimistic vs pessimistic locking | F27: Able to explain concepts in depth | K27: =VLOOKUP(F27,Data!$F$3:$G$7,2,FALSE) -> 0
C28: Hibernate — inheritance strategies (JOINED vs TABLE_PER_CLASS) | F28: Able to explain concepts in depth | K28: =VLOOKUP(F28,Data!$F$3:$G$7,2,FALSE) -> 1
C29: Spring Data JPA — Specification / QueryDSL | F29: Confident hands on developer | K29: =VLOOKUP(F29,Data!$F$3:$G$7,2,FALSE) -> 3
I30: AVG %age SCORE: | J30: =AVERAGE(K31:K36)/3*100 -> 0 | L30: =IF(J30<5,"-",IF(J30<10,"AL2","Sr Associate")) -> -
B31: Transaction Management & Concurrency | C31: Spring — @Transactional propagation (REQUIRED vs REQUIRES_NEW) | F31: Confident hands on developer | G31: [Transaction Management & Concurrency] Smoke test feedback for row 36 — Java — volatile vs AtomicInteger vs LongAdder. | K31: =VLOOKUP(F31,Data!$D$3:$G$7,4,FALSE) -> 0
C32: Spring — @Transactional isolation levels (READ_COMMITTED vs REPEATABLE_READ) | F32: Able to explain concepts in depth | K32: =VLOOKUP(F32,Data!$D$3:$G$7,4,FALSE) -> 0
C33: Java — synchronized vs ReentrantLock vs StampedLock | F33: Confident hands on developer | K33: =VLOOKUP(F33,Data!$D$3:$G$7,4,FALSE) -> 0
C34: Java — ConcurrentHashMap internal segments / computeIfAbsent | F34: Confident hands on developer | K34: =VLOOKUP(F34,Data!$D$3:$G$7,4,FALSE) -> 0
C35: Java — ExecutorService / ThreadPoolExecutor tuning | F35: Able to explain concepts in depth | K35: =VLOOKUP(F35,Data!$D$3:$G$7,4,FALSE) -> 0
C36: Java — volatile vs AtomicInteger vs LongAdder | F36: Confident hands on developer | K36: =VLOOKUP(F36,Data!$D$3:$G$7,4,FALSE) -> 0
I37: AVG %age SCORE: | J37: =AVERAGE(K38:K50)/3*100 -> 0 | L37: =IF(J37<5,"-",IF(J37<10,"AL2","Sr Associate")) -> -
B38: REST, Security & Observability | C38: REST — HATEOAS / Richardson Maturity Model | F38: Able to explain concepts in depth | G38: [REST, Security & Observability] Smoke test feedback for row 43 — Project Reactor — Mono vs Flux / backpressure. | K38: =VLOOKUP(F38,Data!$D$3:$G$7,4,FALSE) -> 0
C39: Spring Security — OAuth2 / JWT token validation | F39: Confident hands on developer | K39: =VLOOKUP(F39,Data!$D$3:$G$7,4,FALSE) -> 0
C40: Spring Security — method security (@PreAuthorize) | F40: Confident hands on developer | K40: =VLOOKUP(F40,Data!$D$3:$G$7,4,FALSE) -> 0
C41: Micrometer — custom metrics / @Timed | F41: Confident hands on developer | K41: =VLOOKUP(F41,Data!$D$3:$G$7,4,FALSE) -> 0
C42: Docker — multi-stage builds / layer caching | F42: Able to explain concepts in depth | K42: =VLOOKUP(F42,Data!$D$3:$G$7,4,FALSE) -> 0
...

Sheet Data
B2: Career Stage | C2: Interview Outcome | D2: Scoring Architecture | E2: Rejection Reason | F2: Scoring Development | G2: Scoring Score | H2: Core XT Training Sections | I2: Will You Take Person | J2: React Training Sections
B3: Experience Engineer L1 | C3: Selected | D3: Did not probe | E3: Lacked Fundamentals | F3: Did not probe | G3: 0 | H3: HTML/CSS | I3: Yes | J3: React Specialist
B4: Experience Engineer L2 | C4: Rejected | D4: No Experience | E4: No Hands on Experience | F4: No Experience | G4: 0 | H4: NFR | I4: No
B5: Senior Experience Engineer | C5: Needs Another Round | D5: Awareness of concepts | E5: Gaps in multiple categories | F5: Able to explain concepts theoritically | G5: 1 | H5: HTML/CSS & NFR
B6: Lead Experience Engineer | D6: Able to explain concepts in depth | F6: Able to code with guidance | G6: 2
B7: Manager Experience Engineering | D7: Confident with decision making & hands on | F7: Confident hands on developer | G7: 3

Sheet _meta
A1: app | B1: interviewly
A2: version | B2: 0.1.0
A3: model_provider | B3: deepseek
A4: model_id | B4: deepseek-v4-flash
A5: generated_at | B5: 2026-05-30T20:06:11.557Z
A6: meeting_id | B6: smoke-react-probeform
A7: transcript_sha256 | B7: 0000000000000000000000000000000000000000000000000000000000000000
A8: recruiter_email | B8: smoke@example.com
A9: bot_user_email | B9: bot@example.com
A10: test_mode | B10: false
A11: fixture_id
