Workbook
Name Career_Stage: Data!$B$3:$B$7
Name Core_Exercise: 'Core Exercise'!$A$2:$A$8
Name Core_XT_Training_Sections: Data!$H$3:$H$5
Name Interview_Outcome: Data!$C$3:$C$5
Name React_Exercise: 'React Exercise'!$A$2:$A$8
Name React_Training_Sections: Data!$J$3
Name Rejection_Reason: Data!$E$3:$E$5
Name Scoring_Architecture: Data!$D$3:$D$7
Name Scoring_Development: Data!$F$3:$F$7
Name Will_You_Take_Person: Data!$I$3:$I$4

Sheet 2 - Python Backend
B2: Experience Engineering Hiring Probe Form [If in doubt REJECT the candidate]
B4: Candidate Name: | C4: Test Candidate | E4: Interviewer Name: | F4: Medha | H4: Interview Outcome: | I4: Selected | M4: React Basics | N4: React Advance | O4: Node | P4: GraphQL | Q4: isRejected | R4: isSAL2 | S4: isSAL1 | T4: isAL1 | U4: isAL2 | V4: Career Stage | W4: React Specialist
B5: Total years of exp.: | C5: 7 | E5: Interviewer OID: | F5: AI-001 | H5: Selected for Level: | I5: Senior Experience Engineer | M5: =L13 -> SAL1 | N5: =L21 -> SAL2 | O5: =L30 -> - | P5: =L37 -> - | Q5: =OR(M5="Rejected",N5="Rejected") -> FALSE | R5: =AND(NOT(Q5),M5="SAL2",N5<>"Associate") -> FALSE | S5: =AND(NOT(Q5),NOT(R5),OR(M5="SAL1",M5="SAL2"),OR(N5<>"Associate",AND(N5="Associate",OR(O5<>"-",P5<>"-")))) -> TRUE | T5: =AND(NOT(Q5),NOT(R5),NOT(S5),M5="Associate",N5="Associate",O5="-", P5="-") -> FALSE | U5: =AND(NOT(Q5),NOT(R5),NOT(S2),NOT(T2)) -> TRUE | V5: =IF(Q5,"REJECTED",IF(R5,"Lead Experience Engineer",IF(S5,"Senior Experience Engineer",IF(T5,"Experience Engineer L1",IF(U5,"Experience Engineer L2","Thinking"))))) -> Senior Experience Engineer | W5: =AND(V5="SAL1",F2="Associate") -> FALSE
B6: Relevant years of exp.: | C6: 5 | E6: (Rev)Shadow Name: | H6: Rejection Reason:
B7: Interviewed for: | C7: Senior Experience Engineer | E7: Recommended Title | F7: =V5 -> Senior Experience Engineer | H7: Sections to be trained on: | I7: Property-based testing (Hypothesis)
B8: Evaluation Date: | C8: 05/30/2026 | E8: Recommended Training | F8: =IF(W5,"React Specialist", "No trainings required") -> No trainings required
B9: Domain Feedback Summary & Key Highlights: | D9: The candidate demonstrated strong proficiency across async Python, ORM, web frameworks, and testing. They clearly explained the asyncio event loop, gather vs create_task vs wait, and blocking pitfalls. They showed hands-on experience with SQLAlchemy 2.x select(), Django ORM F() expressions, and eager loading strategies. They also articulated trade-offs between raw SQL and ORM, and discussed zero-downtime migrations. Weaknesses include limited exposure to property-based testing (Hypothesis) and a lack of depth in some areas like async context managers (only theoretical). Overall, the candidate is well-suited for a Senior Experience Engineer role.
B10: Property-based testing with Hypothesis
B11: Choose hands-on exercise | C11: Shopping Cart | D11: =IFERROR(VLOOKUP(C11,'React Exercise'!A1:B8,2,FALSE),"Choose the exercise from left side column") -> Create a React web application that consumes the https://fakestoreapi.com/carts/2 API and displays a list of products in the cart. For each product in the cart, the application should make an API call to fetch the product details using the ID returned in the cart API and display the product title, price, and image. Note: The https://fakestoreapi.com/products/:id: API returns details for a single product. You will need to make an API call for each product in the cart to fetch the product details.
B12: Skill | C12: Areas To Be Probed / Competency Definition | F12: Evaluated Proficiency Level | G12: Feedback Details
B13: React Basics (Cover maximum listed topics as hands-on coding exercise) | I13: AVG %age SCORE: | J13: =AVERAGE(K14:K20)/3*100 -> 76.190476 | L13: =IF(J13<60, "Rejected",IF(J13<70,"Associate",IF(J13<80,"SAL1","SAL2"))) -> SAL1
B14: Async & Concurrency | C14: asyncio — event loop + coroutine lifecycle | F14: Confident with decision making & hands on | G14: - | K14: =VLOOKUP(F14,Data!$F$3:$G$7,2,FALSE) -> 3
C15: async/await — blocking vs non-blocking I/O pitfalls | F15: Confident hands on developer | K15: =VLOOKUP(F15,Data!$F$3:$G$7,2,FALSE) -> 3
C16: GIL — impact on CPU-bound vs I/O-bound tasks | F16: Confident with decision making & hands on | K16: =VLOOKUP(F16,Data!$F$3:$G$7,2,FALSE) -> 3
C17: asyncio.gather vs asyncio.create_task vs asyncio.wait | F17: Confident hands on developer | K17: =VLOOKUP(F17,Data!$F$3:$G$7,2,FALSE) -> 3
C18: async context managers + async generators | F18: Able to explain concepts theoritically | K18: =VLOOKUP(F18,Data!$F$3:$G$7,2,FALSE) -> 3
C19: uvicorn + gunicorn worker model (async workers) | F19: Did not probe | K19: =VLOOKUP(F19,Data!$F$3:$G$7,2,FALSE) -> 1
C20: async-django — ASGI vs WSGI + middleware | F20: Did not probe | K20: =VLOOKUP(F20,Data!$F$3:$G$7,2,FALSE) -> 0
I21: AVG %age SCORE: | J21: =AVERAGE(K22:K29)/3*100 -> 62.5 | L21: =IF(J21<25,"Rejected",IF(J21<40, "Associate", IF(J21<50,"SAL1","SAL2"))) -> SAL2
B22: ORM & Data Access | C22: SQLAlchemy 2.x — select() vs query() + eager loading | F22: Confident hands on developer | G22: Compared Alembic and Django migrations, and described zero-downtime strategies like phased column addition and shadow tables. | K22: =VLOOKUP(F22,Data!$F$3:$G$7,2,FALSE) -> 1
C23: Django ORM — select_related vs prefetch_related + subqueries | F23: Confident hands on developer | K23: =VLOOKUP(F23,Data!$F$3:$G$7,2,FALSE) -> 1
C24: N+1 query detection and mitigation strategies | F24: Confident with decision making & hands on | K24: =VLOOKUP(F24,Data!$F$3:$G$7,2,FALSE) -> 3
C25: Index design — composite indexes, partial indexes, covering indexes | F25: Confident with decision making & hands on | K25: =VLOOKUP(F25,Data!$F$3:$G$7,2,FALSE) -> 3
C26: SQLAlchemy — session lifecycle + flush vs commit | F26: Confident hands on developer | K26: =VLOOKUP(F26,Data!$F$3:$G$7,2,FALSE) -> 3
C27: Django ORM — F() expressions + annotate vs aggregate | F27: Confident hands on developer | K27: =VLOOKUP(F27,Data!$F$3:$G$7,2,FALSE) -> 0
C28: Raw SQL vs ORM tradeoffs + SQL injection prevention | F28: Confident with decision making & hands on | K28: =VLOOKUP(F28,Data!$F$3:$G$7,2,FALSE) -> 1
C29: Migrations — Alembic vs Django migrations + zero-downtime | F29: Confident with decision making & hands on | K29: =VLOOKUP(F29,Data!$F$3:$G$7,2,FALSE) -> 3
I30: AVG %age SCORE: | J30: =AVERAGE(K31:K36)/3*100 -> 0 | L30: =IF(J30<5,"-",IF(J30<10,"AL2","Sr Associate")) -> -
B31: Web Frameworks & APIs | C31: FastAPI — dependency injection + Depends() scoping | F31: Confident hands on developer | G31: Preferred URL versioning for explicitness, discussed header and content negotiation trade-offs. | K31: =VLOOKUP(F31,Data!$D$3:$G$7,4,FALSE) -> 0
C32: Django REST Framework — serializers + ViewSets vs APIView | F32: Confident hands on developer | K32: =VLOOKUP(F32,Data!$D$3:$G$7,4,FALSE) -> 0
C33: Pydantic v2 — model_validator vs field_validator + custom types | F33: Confident hands on developer | K33: =VLOOKUP(F33,Data!$D$3:$G$7,4,FALSE) -> 0
C34: Middleware — custom middleware for auth/logging/rate limiting | F34: Confident with decision making & hands on | K34: =VLOOKUP(F34,Data!$D$3:$G$7,4,FALSE) -> 0
C35: Background tasks — Celery vs FastAPI BackgroundTasks + task routing | F35: Confident with decision making & hands on | K35: =VLOOKUP(F35,Data!$D$3:$G$7,4,FALSE) -> 0
C36: API versioning strategies — URL vs header vs content negotiation | F36: Confident with decision making & hands on | K36: =VLOOKUP(F36,Data!$D$3:$G$7,4,FALSE) -> 0
I37: AVG %age SCORE: | J37: =AVERAGE(K38:K50)/3*100 -> 0 | L37: =IF(J37<5,"-",IF(J37<10,"AL2","Sr Associate")) -> -
B38: Testing & Type Safety | C38: pytest — fixtures + conftest scoping + parametrize | F38: Confident hands on developer | G38: Explained Protocol vs ABC with a Serializable example, and used TypedDict for API responses. | K38: =VLOOKUP(F38,Data!$D$3:$G$7,4,FALSE) -> 0
C39: mypy — strict mode + type narrowing + overloads | F39: Confident hands on developer | K39: =VLOOKUP(F39,Data!$D$3:$G$7,4,FALSE) -> 0
C40: Mocking — unittest.mock vs pytest-mock + patching strategies | F40: Confident hands on developer | K40: =VLOOKUP(F40,Data!$D$3:$G$7,4,FALSE) -> 0
C41: Integration testing — test containers vs fixtures + database isolation | F41: Confident with decision making & hands on | K41: =VLOOKUP(F41,Data!$D$3:$G$7,4,FALSE) -> 0
C42: Property-based testing — hypothesis + strategies | F42: Awareness of concepts | K42: =VLOOKUP(F42,Data!$D$3:$G$7,4,FALSE) -> 0
...

Sheet Data
B2: Career Stage | C2: Interview Outcome | D2: Scoring Architecture | E2: Rejection Reason | F2: Scoring Development | G2: Scoring Score | H2: Core XT Training Sections | I2: Will You Take Person | J2: React Training Sections
B3: Experience Engineer L1 | C3: Selected | D3: Did not probe | E3: Lacked Fundamentals | F3: Did not probe | G3: 0 | H3: HTML/CSS | I3: Yes | J3: React Specialist
B4: Experience Engineer L2 | C4: Rejected | D4: No Experience | E4: No Hands on Experience | F4: No Experience | G4: 0 | H4: NFR | I4: No
B5: Senior Experience Engineer | C5: Needs Another Round | D5: Awareness of concepts | E5: Gaps in multiple categories | F5: Able to explain concepts theoritically | G5: 1 | H5: HTML/CSS & NFR
B6: Lead Experience Engineer | D6: Able to explain concepts in depth | F6: Able to code with guidance | G6: 2
B7: Manager Experience Engineering | D7: Confident with decision making & hands on | F7: Confident hands on developer | G7: 3

Sheet _meta
A1: app | B1: interviewly
A2: version | B2: 0.1.0
A3: model_provider | B3: deepseek
A4: model_id | B4: deepseek-v4-flash
A5: generated_at | B5: 2026-05-30T13:45:46.126Z
A6: meeting_id | B6: TEST_MODE:python-backend-good-hire
A7: transcript_sha256 | B7: 84959815fe1d114610a7f4e070cb1f7a2a8b060faa3954aed21d9f832912f896
A8: recruiter_email | B8: smoke@example.com
A9: bot_user_email | B9: bot@example.com
A10: test_mode | B10: true
A11: fixture_id | B11: python-backend/good-hire
