Workbook
Name Career_Stage: Data!$B$3:$B$7
Name Core_Exercise: 'Core Exercise'!$A$2:$A$8
Name Core_XT_Training_Sections: Data!$H$3:$H$5
Name Interview_Outcome: Data!$C$3:$C$5
Name React_Exercise: 'React Exercise'!$A$2:$A$8
Name React_Training_Sections: Data!$J$3
Name Rejection_Reason: Data!$E$3:$E$5
Name Scoring_Architecture: Data!$D$3:$D$7
Name Scoring_Development: Data!$F$3:$F$7
Name Will_You_Take_Person: Data!$I$3:$I$4

Sheet 2 - Node Backend
B2: Experience Engineering Hiring Probe Form [If in doubt REJECT the candidate]
B4: Candidate Name: | C4: Gurnoor Kaur | E4: Interviewer Name: | F4: Siddhartha Chatterjee | H4: Interview Outcome: | I4: Selected | M4: React Basics | N4: React Advance | O4: Node | P4: GraphQL | Q4: isRejected | R4: isSAL2 | S4: isSAL1 | T4: isAL1 | U4: isAL2 | V4: Career Stage | W4: React Specialist
B5: Total years of exp.: | C5: 5 | E5: Interviewer OID: | F5: 169695 | H5: Selected for Level: | I5: Senior Experience Engineer | M5: =L13 -> SAL1 | N5: =L21 -> SAL2 | O5: =L30 -> - | P5: =L37 -> - | Q5: =OR(M5="Rejected",N5="Rejected") -> FALSE | R5: =AND(NOT(Q5),M5="SAL2",N5<>"Associate") -> FALSE | S5: =AND(NOT(Q5),NOT(R5),OR(M5="SAL1",M5="SAL2"),OR(N5<>"Associate",AND(N5="Associate",OR(O5<>"-",P5<>"-")))) -> TRUE | T5: =AND(NOT(Q5),NOT(R5),NOT(S5),M5="Associate",N5="Associate",O5="-", P5="-") -> FALSE | U5: =AND(NOT(Q5),NOT(R5),NOT(S2),NOT(T2)) -> TRUE | V5: =IF(Q5,"REJECTED",IF(R5,"Lead Experience Engineer",IF(S5,"Senior Experience Engineer",IF(T5,"Experience Engineer L1",IF(U5,"Experience Engineer L2","Thinking"))))) -> Senior Experience Engineer | W5: =AND(V5="SAL1",F2="Associate") -> FALSE
B6: Relevant years of exp.: | C6: 5 | E6: (Rev)Shadow Name: | H6: Rejection Reason:
B7: Interviewed for: | C7: Senior Experience Engineer | E7: Recommended Title | F7: =V5 -> Senior Experience Engineer | H7: Sections to be trained on:
B8: Evaluation Date: | C8: 46208 | E8: Recommended Training | F8: =IF(W5,"React Specialist", "No trainings required") -> No trainings required
B9: Domain Feedback Summary & Key Highlights: | D9: Gurnoor demonstrated consistent hands-on strength across both foundational and advanced React concepts. She confidently handled the preliminary exercise and branching discussions, showing solid understanding of hooks, component structuring, state management, and rendering optimization. Her approach to forms, asynchronous flows, and nested implementations was practical and well-organized. She independently completed the Shopping Cart exercise and showed good awareness of performance considerations, memoization, and scalable state management patterns using Context and Redux Toolkit. Overall, Gurnoor displayed the level of practical understanding and problem-solving expected from a senior React developer.
B10: Teachable Skill Gap Details:
B11: Choose hands-on exercise | C11: Shopping Cart | D11: =IFERROR(VLOOKUP(C11,'React Exercise'!A1:B8,2,FALSE),"Choose the exercise from left side column") -> Create a React web application that consumes the https://fakestoreapi.com/carts/2 API and displays a list of products in the cart. For each product in the cart, the application should make an API call to fetch the product details using the ID returned in the cart API and display the product title, price, and image. Note: The https://fakestoreapi.com/products/:id: API returns details for a single product. You will need to make an API call for each product in the cart to fetch the product details.
B12: Skill | C12: Areas To Be Probed / Competency Definition | F12: Evaluated Proficiency Level | G12: Feedback Details
B13: React Basics (Cover maximum listed topics as hands-on coding exercise) | I13: AVG %age SCORE: | J13: =AVERAGE(K14:K20)/3*100 -> 76.190476 | L13: =IF(J13<60, "Rejected",IF(J13<70,"Associate",IF(J13<80,"SAL1","SAL2"))) -> SAL1
B14: Runtime & Event Loop | C14: Event Loop — microtasks vs macrotasks order | F14: Confident hands on developer | G14: > Gurnoor was able to successfully complete the preliminary exercise and all corresponding branching questions. > Nonetheless she has good practical knowledge, demonstrates strong grasp of useEffect, useState, useRef, useContext, useReducer, useLayoutEffefct, optimizing component structure and re-renders, along with memoization hooks. > Manages form submission, event binding, AJAX calls, and validation with a structured, practical approach. > She writes structured components as well. | K14: =VLOOKUP(F14,Data!$F$3:$G$7,2,FALSE) -> 3
C15: Worker Threads — shared memory vs message passing | F15: Confident hands on developer | K15: =VLOOKUP(F15,Data!$F$3:$G$7,2,FALSE) -> 3
C16: Streams — backpressure handling with highWaterMark | F16: Confident hands on developer | K16: =VLOOKUP(F16,Data!$F$3:$G$7,2,FALSE) -> 3
C17: Node 20 Test Runner — describe/it vs Jest migration | F17: Confident hands on developer | K17: =VLOOKUP(F17,Data!$F$3:$G$7,2,FALSE) -> 3
C18: ESM vs CJS — interop and package.json exports | F18: Confident hands on developer | K18: =VLOOKUP(F18,Data!$F$3:$G$7,2,FALSE) -> 3
C19: Error Handling — async error propagation and unhandledRejection | F19: Able to explain concepts theoritically | K19: =VLOOKUP(F19,Data!$F$3:$G$7,2,FALSE) -> 1
C20: Cluster vs Worker Threads — scaling strategies | F20: Did not probe | K20: =VLOOKUP(F20,Data!$F$3:$G$7,2,FALSE) -> 0
I21: AVG %age SCORE: | J21: =AVERAGE(K22:K29)/3*100 -> 62.5 | L21: =IF(J21<25,"Rejected",IF(J21<40, "Associate", IF(J21<50,"SAL1","SAL2"))) -> SAL2
B22: Frameworks & API Design | C22: Fastify — schema-based validation and serialization | F22: Able to explain concepts theoritically | G22: > Gurnoor was able to successfully demonstrate fundamental and advanced knowledge and had completed the Shopping Cart exercise with no guidance. > She displayed knowledge in asyncronicity and data sequencing, as well as nested implementations. > Understands global state management, optimizing performance and reducing prop drilling efficiently using useContext hooks and Redux toolkit.. > Differentiates useMemo and useCallback, optimizing renders and preventing unnecessary computations. > Overall has sufficient knowledge for a senior developer when it comes to React. | K22: =VLOOKUP(F22,Data!$F$3:$G$7,2,FALSE) -> 1
C23: NestJS — dependency injection and module scoping | F23: Able to explain concepts theoritically | K23: =VLOOKUP(F23,Data!$F$3:$G$7,2,FALSE) -> 1
C24: Express — middleware error handling and async wrappers | F24: Confident hands on developer | K24: =VLOOKUP(F24,Data!$F$3:$G$7,2,FALSE) -> 3
C25: Zod — schema composition and discriminated unions | F25: Confident hands on developer | K25: =VLOOKUP(F25,Data!$F$3:$G$7,2,FALSE) -> 3
C26: GraphQL — DataLoader batching and caching | F26: Confident hands on developer | K26: =VLOOKUP(F26,Data!$F$3:$G$7,2,FALSE) -> 3
C27: Microservice Patterns — saga vs CQRS tradeoffs | F27: Did not probe | K27: =VLOOKUP(F27,Data!$F$3:$G$7,2,FALSE) -> 0
C28: OpenTelemetry — trace propagation and span context | F28: Able to explain concepts theoritically | K28: =VLOOKUP(F28,Data!$F$3:$G$7,2,FALSE) -> 1
C29: API Versioning — header vs URI vs content negotiation | F29: Confident hands on developer | K29: =VLOOKUP(F29,Data!$F$3:$G$7,2,FALSE) -> 3
I30: AVG %age SCORE: | J30: =AVERAGE(K31:K36)/3*100 -> 0 | L30: =IF(J30<5,"-",IF(J30<10,"AL2","Sr Associate")) -> -
B31: Data & Messaging | C31: Prisma — relation queries and N+1 prevention | F31: Did not probe | G31: Provide details of areas probed along with names of technologies used. | K31: =VLOOKUP(F31,Data!$D$3:$G$7,4,FALSE) -> 0
C32: TypeORM — query builder vs find options performance | F32: Did not probe | K32: =VLOOKUP(F32,Data!$D$3:$G$7,4,FALSE) -> 0
C33: BullMQ — job lifecycle and rate limiting | F33: Did not probe | K33: =VLOOKUP(F33,Data!$D$3:$G$7,4,FALSE) -> 0
C34: Redis — pub/sub vs streams for message queues | F34: Did not probe | K34: =VLOOKUP(F34,Data!$D$3:$G$7,4,FALSE) -> 0
C35: Database Migrations — rollback strategies and zero-downtime | F35: Did not probe | K35: =VLOOKUP(F35,Data!$D$3:$G$7,4,FALSE) -> 0
C36: Caching — Redis TTL and cache invalidation patterns | F36: Did not probe | K36: =VLOOKUP(F36,Data!$D$3:$G$7,4,FALSE) -> 0
I37: AVG %age SCORE: | J37: =AVERAGE(K38:K50)/3*100 -> 0 | L37: =IF(J37<5,"-",IF(J37<10,"AL2","Sr Associate")) -> -
B38: Tooling & Observability | C38: pnpm — workspace protocol and dependency hoisting | F38: Did not probe | G38: Provide details of areas probed along with names of technologies used. | K38: =VLOOKUP(F38,Data!$D$3:$G$7,4,FALSE) -> 0
C39: Vitest — mocking and coverage with c8 | F39: Did not probe | K39: =VLOOKUP(F39,Data!$D$3:$G$7,4,FALSE) -> 0
C40: Docker — multi-stage builds and layer caching | F40: Did not probe | K40: =VLOOKUP(F40,Data!$D$3:$G$7,4,FALSE) -> 0
C41: Node 20 — native fetch and undici | F41: Did not probe | K41: =VLOOKUP(F41,Data!$D$3:$G$7,4,FALSE) -> 0
C42: Logging — structured logging and correlation IDs | F42: Did not probe | K42: =VLOOKUP(F42,Data!$D$3:$G$7,4,FALSE) -> 0
...

Sheet Data
B2: Career Stage | C2: Interview Outcome | D2: Scoring Architecture | E2: Rejection Reason | F2: Scoring Development | G2: Scoring Score | H2: Core XT Training Sections | I2: Will You Take Person | J2: React Training Sections
B3: Experience Engineer L1 | C3: Selected | D3: Did not probe | E3: Lacked Fundamentals | F3: Did not probe | G3: 0 | H3: HTML/CSS | I3: Yes | J3: React Specialist
B4: Experience Engineer L2 | C4: Rejected | D4: No Experience | E4: No Hands on Experience | F4: No Experience | G4: 0 | H4: NFR | I4: No
B5: Senior Experience Engineer | C5: Needs Another Round | D5: Awareness of concepts | E5: Gaps in multiple categories | F5: Able to explain concepts theoritically | G5: 1 | H5: HTML/CSS & NFR
B6: Lead Experience Engineer | D6: Able to explain concepts in depth | F6: Able to code with guidance | G6: 2
B7: Manager Experience Engineering | D7: Confident with decision making & hands on | F7: Confident hands on developer | G7: 3
